[2024-09-13 21:14:14,765: INFO: comon: yaml file: config\config.yaml loaded successfully]
[2024-09-13 21:16:22,243: INFO: comon: yaml file: config\config.yaml loaded successfully]
[2024-09-13 21:19:35,508: INFO: comon: yaml file: config\config.yaml loaded successfully]
[2024-09-13 21:20:12,084: INFO: comon: yaml file: config\config.yaml loaded successfully]
[2024-09-13 21:25:00,641: INFO: comon: yaml file: config\config.yaml loaded successfully]
[2024-09-13 21:25:29,845: INFO: comon: yaml file: config\config.yaml loaded successfully]
[2024-09-13 21:29:40,987: INFO: comon: yaml file: config\config.yaml loaded successfully]
[2024-09-13 21:29:40,992: INFO: comon: yaml file: params.yaml loaded successfully]
[2024-09-13 21:29:40,994: INFO: comon: created directory at: artifacts]
[2024-09-13 21:29:40,995: INFO: comon: created directory at: artifacts/data_ingestion]
[2024-09-13 21:29:40,997: INFO: 1518292854: Downloading data from https://drive.google.com/file/d/1OBpczN6HAor-6r1rOQhTUATM59JSPCpp/view?usp=drive_link into file artifacts/data_ingestion/data.zip]
[2024-09-13 21:31:25,996: INFO: 1518292854: Downloaded data from https://drive.google.com/file/d/1OBpczN6HAor-6r1rOQhTUATM59JSPCpp/view?usp=drive_link into file artifacts/data_ingestion/data.zip]
[2024-09-13 22:37:58,041: INFO: main: >>>>>> stage Data Ingestion stage started <<<<<<]
[2024-09-13 22:37:58,042: INFO: comon: yaml file: config\config.yaml loaded successfully]
[2024-09-13 22:37:58,044: INFO: comon: yaml file: params.yaml loaded successfully]
[2024-09-13 22:37:58,045: INFO: comon: created directory at: artifacts]
[2024-09-13 22:37:58,047: INFO: comon: created directory at: artifacts/data_ingestion]
[2024-09-13 22:37:58,048: INFO: data_ingestion: Downloading data from https://drive.google.com/file/d/1OBpczN6HAor-6r1rOQhTUATM59JSPCpp/view?usp=drive_link into file artifacts/data_ingestion/data.zip]
[2024-09-13 22:39:02,067: INFO: data_ingestion: Downloaded data from https://drive.google.com/file/d/1OBpczN6HAor-6r1rOQhTUATM59JSPCpp/view?usp=drive_link into file artifacts/data_ingestion/data.zip]
[2024-09-13 22:39:05,383: INFO: main: >>>>>> stage Data Ingestion stage completed <<<<<<

x==========x]
[2024-09-14 00:44:54,912: INFO: main: >>>>>> stage Data Ingestion stage started <<<<<<]
[2024-09-14 00:44:54,919: INFO: comon: yaml file: config\config.yaml loaded successfully]
[2024-09-14 00:44:54,926: INFO: comon: yaml file: params.yaml loaded successfully]
[2024-09-14 00:44:54,930: INFO: comon: created directory at: artifacts]
[2024-09-14 00:44:54,933: INFO: comon: created directory at: artifacts/prepare_base_model]
[2024-09-14 00:44:54,935: INFO: data_ingestion: Downloading data from https://drive.google.com/file/d/1OBpczN6HAor-6r1rOQhTUATM59JSPCpp/view?usp=drive_link into file artifacts/data_ingestion/data.zip]
[2024-09-14 00:45:38,347: INFO: data_ingestion: Downloaded data from https://drive.google.com/file/d/1OBpczN6HAor-6r1rOQhTUATM59JSPCpp/view?usp=drive_link into file artifacts/data_ingestion/data.zip]
[2024-09-14 00:45:47,268: INFO: main: >>>>>> stage Data Ingestion stage completed <<<<<<

x==========x]
[2024-09-14 00:45:47,271: INFO: main: *******************]
[2024-09-14 00:45:47,272: INFO: main: >>>>>> stage Prepare base model started <<<<<<]
[2024-09-14 00:45:47,285: INFO: comon: yaml file: config\config.yaml loaded successfully]
[2024-09-14 00:45:47,290: INFO: comon: yaml file: params.yaml loaded successfully]
[2024-09-14 00:45:47,292: INFO: comon: created directory at: artifacts]
[2024-09-14 00:45:47,325: ERROR: main: "'ConfigBox' object has no attribute 'prepare_base_model'"]
Traceback (most recent call last):
  File "box\box.py", line 503, in box.box.Box.__getitem__
KeyError: 'prepare_base_model'

The above exception was the direct cause of the following exception:

Traceback (most recent call last):
  File "box\box.py", line 536, in box.box.Box.__getattr__
  File "box\box.py", line 524, in box.box.Box.__getitem__
box.exceptions.BoxKeyError: "'prepare_base_model'"

During handling of the above exception, another exception occurred:

Traceback (most recent call last):
  File "box\box.py", line 538, in box.box.Box.__getattr__
AttributeError: 'ConfigBox' object has no attribute 'prepare_base_model'

The above exception was the direct cause of the following exception:

Traceback (most recent call last):
  File "box\config_box.py", line 28, in box.config_box.ConfigBox.__getattr__
  File "box\box.py", line 552, in box.box.Box.__getattr__
box.exceptions.BoxKeyError: "'ConfigBox' object has no attribute 'prepare_base_model'"

During handling of the above exception, another exception occurred:

Traceback (most recent call last):
  File "box\box.py", line 503, in box.box.Box.__getitem__
KeyError: 'prepare_base_model'

The above exception was the direct cause of the following exception:

Traceback (most recent call last):
  File "box\box.py", line 536, in box.box.Box.__getattr__
  File "box\box.py", line 524, in box.box.Box.__getitem__
box.exceptions.BoxKeyError: "'prepare_base_model'"

During handling of the above exception, another exception occurred:

Traceback (most recent call last):
  File "box\box.py", line 538, in box.box.Box.__getattr__
AttributeError: 'ConfigBox' object has no attribute 'prepare_base_model'

The above exception was the direct cause of the following exception:

Traceback (most recent call last):
  File "templates/main.py", line 31, in <module>
    prepare_base_model.main()
  File "c:\users\shuda\end-to-end-with-mlflow\src\cnnClassifier\pipeline\stage_02_prepare_base_model.py", line 16, in main
    prepare_base_model_config = config.get_prepare_base_model_config()
  File "c:\users\shuda\end-to-end-with-mlflow\src\cnnClassifier\config\configuration.py", line 38, in get_prepare_base_model_config
    config = self.config.prepare_base_model
  File "box\config_box.py", line 30, in box.config_box.ConfigBox.__getattr__
  File "box\box.py", line 552, in box.box.Box.__getattr__
box.exceptions.BoxKeyError: "'ConfigBox' object has no attribute 'prepare_base_model'"
[2024-09-15 00:06:31,356: INFO: main: >>>>>> stage Data Ingestion stage started <<<<<<]
[2024-09-15 00:06:31,360: INFO: comon: yaml file: config\config.yaml loaded successfully]
[2024-09-15 00:06:31,365: INFO: comon: yaml file: params.yaml loaded successfully]
[2024-09-15 00:06:31,366: INFO: comon: created directory at: artifacts]
[2024-09-15 00:06:31,367: INFO: comon: created directory at: artifacts/prepare_base_model]
[2024-09-15 00:06:31,367: INFO: data_ingestion: Downloading data from https://drive.google.com/file/d/1OBpczN6HAor-6r1rOQhTUATM59JSPCpp/view?usp=drive_link into file artifacts/data_ingestion/data.zip]
[2024-09-15 00:07:13,708: INFO: data_ingestion: Downloaded data from https://drive.google.com/file/d/1OBpczN6HAor-6r1rOQhTUATM59JSPCpp/view?usp=drive_link into file artifacts/data_ingestion/data.zip]
[2024-09-15 00:07:17,516: INFO: main: >>>>>> stage Data Ingestion stage completed <<<<<<

x==========x]
[2024-09-15 00:07:17,517: INFO: main: *******************]
[2024-09-15 00:07:17,517: INFO: main: >>>>>> stage Prepare base model started <<<<<<]
[2024-09-15 00:07:17,519: INFO: comon: yaml file: config\config.yaml loaded successfully]
[2024-09-15 00:07:17,521: INFO: comon: yaml file: params.yaml loaded successfully]
[2024-09-15 00:07:17,522: INFO: comon: created directory at: artifacts]
[2024-09-15 00:07:17,535: ERROR: main: "'ConfigBox' object has no attribute 'prepare_base_model'"]
Traceback (most recent call last):
  File "box\box.py", line 503, in box.box.Box.__getitem__
KeyError: 'prepare_base_model'

The above exception was the direct cause of the following exception:

Traceback (most recent call last):
  File "box\box.py", line 536, in box.box.Box.__getattr__
  File "box\box.py", line 524, in box.box.Box.__getitem__
box.exceptions.BoxKeyError: "'prepare_base_model'"

During handling of the above exception, another exception occurred:

Traceback (most recent call last):
  File "box\box.py", line 538, in box.box.Box.__getattr__
AttributeError: 'ConfigBox' object has no attribute 'prepare_base_model'

The above exception was the direct cause of the following exception:

Traceback (most recent call last):
  File "box\config_box.py", line 28, in box.config_box.ConfigBox.__getattr__
  File "box\box.py", line 552, in box.box.Box.__getattr__
box.exceptions.BoxKeyError: "'ConfigBox' object has no attribute 'prepare_base_model'"

During handling of the above exception, another exception occurred:

Traceback (most recent call last):
  File "box\box.py", line 503, in box.box.Box.__getitem__
KeyError: 'prepare_base_model'

The above exception was the direct cause of the following exception:

Traceback (most recent call last):
  File "box\box.py", line 536, in box.box.Box.__getattr__
  File "box\box.py", line 524, in box.box.Box.__getitem__
box.exceptions.BoxKeyError: "'prepare_base_model'"

During handling of the above exception, another exception occurred:

Traceback (most recent call last):
  File "box\box.py", line 538, in box.box.Box.__getattr__
AttributeError: 'ConfigBox' object has no attribute 'prepare_base_model'

The above exception was the direct cause of the following exception:

Traceback (most recent call last):
  File "templates/main.py", line 31, in <module>
    prepare_base_model.main()
  File "c:\users\shuda\end-to-end-with-mlflow\src\cnnClassifier\pipeline\stage_02_prepare_base_model.py", line 16, in main
    prepare_base_model_config = config.get_prepare_base_model_config()
  File "c:\users\shuda\end-to-end-with-mlflow\src\cnnClassifier\config\configuration.py", line 38, in get_prepare_base_model_config
    config = self.config.prepare_base_model
  File "box\config_box.py", line 30, in box.config_box.ConfigBox.__getattr__
  File "box\box.py", line 552, in box.box.Box.__getattr__
box.exceptions.BoxKeyError: "'ConfigBox' object has no attribute 'prepare_base_model'"
[2024-09-15 00:08:23,017: INFO: main: >>>>>> stage Data Ingestion stage started <<<<<<]
[2024-09-15 00:08:23,020: INFO: comon: yaml file: config\config.yaml loaded successfully]
[2024-09-15 00:08:23,022: INFO: comon: yaml file: params.yaml loaded successfully]
[2024-09-15 00:08:23,023: INFO: comon: created directory at: artifacts]
[2024-09-15 00:08:23,024: INFO: comon: created directory at: artifacts/prepare_base_model]
[2024-09-15 00:08:23,025: INFO: data_ingestion: Downloading data from https://drive.google.com/file/d/1OBpczN6HAor-6r1rOQhTUATM59JSPCpp/view?usp=drive_link into file artifacts/data_ingestion/data.zip]
[2024-09-15 00:09:03,305: INFO: data_ingestion: Downloaded data from https://drive.google.com/file/d/1OBpczN6HAor-6r1rOQhTUATM59JSPCpp/view?usp=drive_link into file artifacts/data_ingestion/data.zip]
[2024-09-15 00:09:07,707: INFO: main: >>>>>> stage Data Ingestion stage completed <<<<<<

x==========x]
[2024-09-15 00:09:07,709: INFO: main: *******************]
[2024-09-15 00:09:07,710: INFO: main: >>>>>> stage Prepare base model started <<<<<<]
[2024-09-15 00:09:07,716: INFO: comon: yaml file: config\config.yaml loaded successfully]
[2024-09-15 00:09:07,720: INFO: comon: yaml file: params.yaml loaded successfully]
[2024-09-15 00:09:07,722: INFO: comon: created directory at: artifacts]
[2024-09-15 00:09:07,850: ERROR: main: "'ConfigBox' object has no attribute 'prepare_base_model'"]
Traceback (most recent call last):
  File "box\box.py", line 503, in box.box.Box.__getitem__
KeyError: 'prepare_base_model'

The above exception was the direct cause of the following exception:

Traceback (most recent call last):
  File "box\box.py", line 536, in box.box.Box.__getattr__
  File "box\box.py", line 524, in box.box.Box.__getitem__
box.exceptions.BoxKeyError: "'prepare_base_model'"

During handling of the above exception, another exception occurred:

Traceback (most recent call last):
  File "box\box.py", line 538, in box.box.Box.__getattr__
AttributeError: 'ConfigBox' object has no attribute 'prepare_base_model'

The above exception was the direct cause of the following exception:

Traceback (most recent call last):
  File "box\config_box.py", line 28, in box.config_box.ConfigBox.__getattr__
  File "box\box.py", line 552, in box.box.Box.__getattr__
box.exceptions.BoxKeyError: "'ConfigBox' object has no attribute 'prepare_base_model'"

During handling of the above exception, another exception occurred:

Traceback (most recent call last):
  File "box\box.py", line 503, in box.box.Box.__getitem__
KeyError: 'prepare_base_model'

The above exception was the direct cause of the following exception:

Traceback (most recent call last):
  File "box\box.py", line 536, in box.box.Box.__getattr__
  File "box\box.py", line 524, in box.box.Box.__getitem__
box.exceptions.BoxKeyError: "'prepare_base_model'"

During handling of the above exception, another exception occurred:

Traceback (most recent call last):
  File "box\box.py", line 538, in box.box.Box.__getattr__
AttributeError: 'ConfigBox' object has no attribute 'prepare_base_model'

The above exception was the direct cause of the following exception:

Traceback (most recent call last):
  File "templates/main.py", line 31, in <module>
    prepare_base_model.main()
  File "c:\users\shuda\end-to-end-with-mlflow\src\cnnClassifier\pipeline\stage_02_prepare_base_model.py", line 16, in main
    prepare_base_model_config = config.get_prepare_base_model_config()
  File "c:\users\shuda\end-to-end-with-mlflow\src\cnnClassifier\config\configuration.py", line 38, in get_prepare_base_model_config
    config = self.config.prepare_base_model
  File "box\config_box.py", line 30, in box.config_box.ConfigBox.__getattr__
  File "box\box.py", line 552, in box.box.Box.__getattr__
box.exceptions.BoxKeyError: "'ConfigBox' object has no attribute 'prepare_base_model'"
[2024-09-15 00:13:02,190: INFO: main: >>>>>> stage Data Ingestion stage started <<<<<<]
[2024-09-15 00:13:02,196: INFO: comon: yaml file: config\config.yaml loaded successfully]
[2024-09-15 00:13:02,203: INFO: comon: yaml file: params.yaml loaded successfully]
[2024-09-15 00:13:02,207: INFO: comon: created directory at: artifacts]
[2024-09-15 00:13:02,209: INFO: comon: created directory at: artifacts/data_ingestion]
[2024-09-15 00:13:02,210: INFO: data_ingestion: Downloading data from https://drive.google.com/file/d/1OBpczN6HAor-6r1rOQhTUATM59JSPCpp/view?usp=drive_link into file artifacts/data_ingestion/data.zip]
[2024-09-15 00:13:40,481: INFO: data_ingestion: Downloaded data from https://drive.google.com/file/d/1OBpczN6HAor-6r1rOQhTUATM59JSPCpp/view?usp=drive_link into file artifacts/data_ingestion/data.zip]
[2024-09-15 00:13:44,383: INFO: main: >>>>>> stage Data Ingestion stage completed <<<<<<

x==========x]
[2024-09-15 00:13:44,383: INFO: main: *******************]
[2024-09-15 00:13:44,384: INFO: main: >>>>>> stage Prepare base model started <<<<<<]
[2024-09-15 00:13:44,389: INFO: comon: yaml file: config\config.yaml loaded successfully]
[2024-09-15 00:13:44,392: INFO: comon: yaml file: params.yaml loaded successfully]
[2024-09-15 00:13:44,392: INFO: comon: created directory at: artifacts]
[2024-09-15 00:13:44,404: INFO: comon: created directory at: artifacts/prepare_base_model]
[2024-09-15 00:14:00,618: WARNING: saving_utils: Compiled the loaded model, but the compiled metrics have yet to be built. `model.compile_metrics` will be empty until you train or evaluate the model.]
[2024-09-15 00:14:02,528: INFO: main: >>>>>> stage Prepare base model completed <<<<<<

x==========x]
